process.on('beforeExit', () => {
  console.log('el proceso va a terminar');
});

process.on('exit', () => {
  console.log('Ale, el proceso acabÃ³');
  setTimeout(() => {
    console.log('Esto no se va a ver nunca');
  }, 0);
});

process.on('uncaughtException', (err, origen) => {
  console.error('Vaya se nos ha olvidado capturar un error');
  setTimeout(() => {
    console.log('Esto viene desde las excepciones');
  }, 0);
});

setTimeout(() => {
  console.log('Esto si se va a ver');
}, 0);

funcionQuenoExiste();

console.log('Si el error no se recoge no sale');


console.log('entra', () => {
  console.log('otro');
});